<?xml version="1.0" encoding="utf-8"?>
<!-- This URDF was automatically created by SolidWorks to URDF Exporter! Originally created by Stephen Brawner (brawner@gmail.com) 
     Commit Version: 1.6.0-1-g15f4949  Build Version: 1.6.7594.29634
     For more information, please see http://wiki.ros.org/sw_urdf_exporter -->
<robot
  name="robot_arm">
  <link
    name="base_link">
    <inertial>
      <origin
        xyz="0.022652 -0.0003057 0.019892"
        rpy="0 0 0" />
      <mass
        value="0.45128" />
      <inertia
        ixx="0.00035865"
        ixy="9.1464E-06"
        ixz="4.2732E-05"
        iyy="0.00078559"
        iyz="7.4208E-07"
        izz="0.00099342" />
    </inertial>
    <visual>
      <origin
        xyz="0 0 0"
        rpy="0 0 0" />
      <geometry>
        <mesh
          filename="package://robot_arm/meshes/base_link.STL" />
      </geometry>
      <material
        name="">
        <color
          rgba="0.9098 0.44314 0.031373 1" />
      </material>
    </visual>
    <collision>
      <origin
        xyz="0 0 0"
        rpy="0 0 0" />
      <geometry>
        <mesh
          filename="package://robot_arm/meshes/base_link.STL" />
      </geometry>
    </collision>
  </link>
  <link
    name="Link_1">
    <inertial>
      <origin
        xyz="-0.019819 -0.050582 5.648E-07"
        rpy="0 0 0" />
      <mass
        value="0.2999" />
      <inertia
        ixx="0.00046491"
        ixy="-0.00019294"
        ixz="-6.3645E-10"
        iyy="0.00028239"
        iyz="-1.4246E-09"
        izz="0.00058439" />
    </inertial>
    <visual>
      <origin
        xyz="0 0 0"
        rpy="0 0 0" />
      <geometry>
        <mesh
          filename="package://robot_arm/meshes/Link_1.STL" />
      </geometry>
      <material
        name="">
        <color
          rgba="1 1 0.50196 1" />
      </material>
    </visual>
    <collision>
      <origin
        xyz="0 0 0"
        rpy="0 0 0" />
      <geometry>
        <mesh
          filename="package://robot_arm/meshes/Link_1.STL" />
      </geometry>
    </collision>
  </link>
  <joint
    name="Joint_1"
    type="revolute">
    <origin
      xyz="0 0 0.045"
      rpy="-1.5708 0 -1.0577" />
    <parent
      link="base_link" />
    <child
      link="Link_1" />
    <axis
      xyz="0 -1 0" />
    <limit
      lower="-3.14"
      upper="3.14"
      effort="200"
      velocity="3" />
  </joint>
  <link
    name="Link_2">
    <inertial>
      <origin
        xyz="0.040634 0.00089632 -4.2115E-09"
        rpy="0 0 0" />
      <mass
        value="0.11006" />
      <inertia
        ixx="2.1883E-05"
        ixy="-1.8735E-06"
        ixz="6.9081E-12"
        iyy="0.00010675"
        iyz="1.5891E-11"
        izz="0.00010767" />
    </inertial>
    <visual>
      <origin
        xyz="0 0 0"
        rpy="0 0 0" />
      <geometry>
        <mesh
          filename="package://robot_arm/meshes/Link_2.STL" />
      </geometry>
      <material
        name="">
        <color
          rgba="1 0.50196 0.50196 1" />
      </material>
    </visual>
    <collision>
      <origin
        xyz="0 0 0"
        rpy="0 0 0" />
      <geometry>
        <mesh
          filename="package://robot_arm/meshes/Link_2.STL" />
      </geometry>
    </collision>
  </link>
  <joint
    name="Joint_2"
    type="revolute">
    <origin
      xyz="-0.05 -0.1 0"
      rpy="0 0 -0.23131" />
    <parent
      link="Link_1" />
    <child
      link="Link_2" />
    <axis
      xyz="0 0 1" />
    <limit
      lower="0"
      upper="2.61"
      effort="100"
      velocity="3" />
  </joint>
  <link
    name="Link_3">
    <inertial>
      <origin
        xyz="0.049603 -6.5616E-10 2.0554E-08"
        rpy="0 0 0" />
      <mass
        value="0.055235" />
      <inertia
        ixx="7.2414E-06"
        ixy="7.0952E-13"
        ixz="-1.214E-11"
        iyy="6.7372E-05"
        iyz="6.2077E-11"
        izz="6.3743E-05" />
    </inertial>
    <visual>
      <origin
        xyz="0 0 0"
        rpy="0 0 0" />
      <geometry>
        <mesh
          filename="package://robot_arm/meshes/Link_3.STL" />
      </geometry>
      <material
        name="">
        <color
          rgba="0.50196 1 0.50196 1" />
      </material>
    </visual>
    <collision>
      <origin
        xyz="0 0 0"
        rpy="0 0 0" />
      <geometry>
        <mesh
          filename="package://robot_arm/meshes/Link_3.STL" />
      </geometry>
    </collision>
  </link>
  <joint
    name="Joint_3"
    type="revolute">
    <origin
      xyz="0.089978 0.0019852 0"
      rpy="0 0 0.074747" />
    <parent
      link="Link_2" />
    <child
      link="Link_3" />
    <axis
      xyz="0 0 -1" />
    <limit
      lower="-0.174"
      upper="1.74"
      effort="100"
      velocity="3" />
  </joint>
  <link
    name="Link4">
    <inertial>
      <origin
        xyz="0.021961 -8.3267E-17 3.1289E-05"
        rpy="0 0 0" />
      <mass
        value="0.012616" />
      <inertia
        ixx="6.5519E-07"
        ixy="1.1316E-21"
        ixz="4.6978E-21"
        iyy="2.2097E-06"
        iyz="8.1144E-23"
        izz="2.212E-06" />
    </inertial>
    <visual>
      <origin
        xyz="0 0 0"
        rpy="0 0 0" />
      <geometry>
        <mesh
          filename="package://robot_arm/meshes/Link4.STL" />
      </geometry>
      <material
        name="">
        <color
          rgba="1 1 0.75294 1" />
      </material>
    </visual>
    <collision>
      <origin
        xyz="0 0 0"
        rpy="0 0 0" />
      <geometry>
        <mesh
          filename="package://robot_arm/meshes/Link4.STL" />
      </geometry>
    </collision>
  </link>
  <joint
    name="Joint_4"
    type="revolute">
    <origin
      xyz="0.108 0 0"
      rpy="0 0 0.0020315" />
    <parent
      link="Link_3" />
    <child
      link="Link4" />
    <axis
      xyz="0 0 1" />
    <limit
      lower="-2.68"
      upper="1.3"
      effort="100"
      velocity="3" />
  </joint>
</robot>